Traceback (most recent call last):
  File "/Library/Frameworks/Python.framework/Versions/3.5/lib/python3.5/copy.py", line 265, in _keep_alive
    memo[id(memo)].append(x)
KeyError: 4321339400

During handling of the above exception, another exception occurred:

Traceback (most recent call last):
  File "/Library/Frameworks/Python.framework/Versions/3.5/lib/python3.5/copy.py", line 268, in _keep_alive
    memo[id(memo)]=[x]
KeyboardInterrupt
