Failed to import the site module
Traceback (most recent call last):
  File "/Library/Frameworks/Python.framework/Versions/3.5/lib/python3.5/site.py", line 563, in <module>
    main()
  File "/Library/Frameworks/Python.framework/Versions/3.5/lib/python3.5/site.py", line 549, in main
    known_paths = addusersitepackages(known_paths)
  File "/Library/Frameworks/Python.framework/Versions/3.5/lib/python3.5/site.py", line 281, in addusersitepackages
    user_site = getusersitepackages()
  File "/Library/Frameworks/Python.framework/Versions/3.5/lib/python3.5/site.py", line 257, in getusersitepackages
    user_base = getuserbase() # this will also set USER_BASE
  File "/Library/Frameworks/Python.framework/Versions/3.5/lib/python3.5/site.py", line 247, in getuserbase
    USER_BASE = get_config_var('userbase')
  File "/Library/Frameworks/Python.framework/Versions/3.5/lib/python3.5/sysconfig.py", line 582, in get_config_var
    return get_config_vars().get(name)
  File "/Library/Frameworks/Python.framework/Versions/3.5/lib/python3.5/sysconfig.py", line 561, in get_config_vars
    import _osx_support
  File "/Library/Frameworks/Python.framework/Versions/3.5/lib/python3.5/_osx_support.py", line 4, in <module>
    import re
  File "/Library/Frameworks/Python.framework/Versions/3.5/lib/python3.5/re.py", line 335, in <module>
    import copyreg
  File "<frozen importlib._bootstrap>", line 969, in _find_and_load
  File "<frozen importlib._bootstrap>", line 954, in _find_and_load_unlocked
  File "<frozen importlib._bootstrap>", line 896, in _find_spec
  File "<frozen importlib._bootstrap_external>", line 1136, in find_spec
  File "<frozen importlib._bootstrap_external>", line 1105, in _get_spec
KeyboardInterrupt
